I'm sorry, but an uncaught exception occurred.

While running game code:
WindowsError: [Error 32] The process cannot access the file because it is being used by another process: u'D:\\VN direct\\koor_prep/game\\saves\\persistent'

-- Full Traceback ------------------------------------------------------------

Full traceback:
  File "C:\Users\ferro\Desktop\SI UMN\VN Code\renpy-7.4.10-sdk/renpy/bootstrap.py", line 331, in bootstrap
    renpy.main.main()
  File "C:\Users\ferro\Desktop\SI UMN\VN Code\renpy-7.4.10-sdk/renpy/main.py", line 665, in main
    renpy.persistent.update(True)
  File "C:\Users\ferro\Desktop\SI UMN\VN Code\renpy-7.4.10-sdk/renpy/persistent.py", line 395, in update
    save()
  File "C:\Users\ferro\Desktop\SI UMN\VN Code\renpy-7.4.10-sdk/renpy/persistent.py", line 411, in save
    renpy.loadsave.location.save_persistent(data)
  File "C:\Users\ferro\Desktop\SI UMN\VN Code\renpy-7.4.10-sdk/renpy/savelocation.py", line 496, in save_persistent
    l.save_persistent(data)
  File "C:\Users\ferro\Desktop\SI UMN\VN Code\renpy-7.4.10-sdk/renpy/savelocation.py", line 351, in save_persistent
    safe_rename(fn_new, fn)
  File "C:\Users\ferro\Desktop\SI UMN\VN Code\renpy-7.4.10-sdk/renpy/loadsave.py", line 304, in safe_rename
    os.unlink(new)
WindowsError: [Error 32] The process cannot access the file because it is being used by another process: u'D:\\VN direct\\koor_prep/game\\saves\\persistent'

Windows-10-10.0.19041
Ren'Py 7.4.11.2266
koor_prep 1.0
Fri Jul  8 22:52:19 2022
